<?xml version="1.0" ?>
<sdf version="1.7">
<model name='axial_scx10'>
  <pose>0 0 0.15 0 0 0</pose>

  <link name='base_link'>
    <inertial>
        <mass>1</mass>
        <inertia>
          <ixx>0.1</ixx>
          <iyy>0.1</iyy>
          <izz>0.1</izz>
        </inertia>
      </inertial>


    <collision name='collision body'>
      <geometry>
        <box>
          <size>0.46 0.225 0.08</size>
        </box>
      </geometry>
    </collision>

    <visual name='visual body'>
      <geometry>
        <box>
          <size>0.46 0.225 0.08</size>
        </box>
      </geometry>

      <material>
        <ambient>0.3 0.4 0.2 </ambient>
        <diffuse>0.4 0.5 0.3 </diffuse>
      </material>
    </visual>

    <visual name='cage'>
      <pose>-0.08 0 0.08 0 0 0</pose>
      <geometry>
        <box>
          <size>0.3 0.2 0.08</size>
        </box>
      </geometry>

      <material>
        <script>
          <uri>file://media/materials/scripts/gazebo.material</uri>
          <name>Gazebo/DarkGrey</name>
        </script>
      </material>

    </visual>

    <collision name='collision cage'>
      <pose>-0.08 0 0.08 0 0 0</pose>
      <geometry>
        <box>
          <size>0.3 0.2 0.08</size>
        </box>
      </geometry>
    </collision>


  </link>

  
  <link name="front_left_strut">
    <inertial>
        <mass>0.01</mass>
        <inertia>
          <ixx>0.001</ixx>
          <iyy>0.001</iyy>
          <izz>0.001</izz>
        </inertia>
      </inertial>

    <pose>0.15 0.08 -0.08 0 0 0</pose>
  </link>

  <link name="front_left_wheel">
    <pose>0.15 0.08 -0.08 -1.5707 0 0</pose>
    <inertial>
        <mass>0.01</mass>
        <inertia>
          <ixx>0.001</ixx>
          <iyy>0.001</iyy>
          <izz>0.001</izz>
        </inertia>
      </inertial>

    <collision name="collision">
      <geometry>
        <cylinder>
          <radius>0.055</radius>
          <length>0.04</length>
        </cylinder>
      </geometry>
    </collision>

    <visual name="tire">
      <geometry>
        <cylinder>
          <radius>0.055</radius>
          <length>0.04</length>
        </cylinder>
      </geometry>
      <material>
        <script>
          <uri>file://media/materials/scripts/gazebo.material</uri>
          <name>Gazebo/DarkGrey</name>
        </script>
      </material>
    </visual>

  </link>

  
  <joint type="revolute" name="front_left_steer_joint">
    <parent>base_link</parent>
    <child>front_left_strut</child>
    <axis>
      <xyz>0 0 1</xyz> 
      <limit>
        <lower>-1</lower>
        <upper>1</upper>
        <velocity>1.0</velocity>
        <effort>25</effort>
      </limit>
    </axis>
  </joint>
  

  <joint type="revolute" name="front_left_drive_joint">
    <parent>front_left_strut</parent>
    <child>front_left_wheel</child>
    <axis>
      <xyz>0 0 1</xyz>
      <limit>
        <lower>-1.79769e+308</lower>
        <upper>1.79769e+308</upper>
      </limit>
    </axis>
  </joint>
  
  <link name="front_right_strut">
    <inertial>
        <mass>0.01</mass>
        <inertia>
          <ixx>0.001</ixx>
          <iyy>0.001</iyy>
          <izz>0.001</izz>
        </inertia>
      </inertial>

    <pose>0.15 -0.08 -0.08 0 0 0</pose>
  </link>

  <link name="front_right_wheel">
    <pose>0.15 -0.08 -0.08 -1.5707 0 0</pose>
    <inertial>
        <mass>0.01</mass>
        <inertia>
          <ixx>0.001</ixx>
          <iyy>0.001</iyy>
          <izz>0.001</izz>
        </inertia>
      </inertial>

    <collision name="collision">
      <geometry>
        <cylinder>
          <radius>0.055</radius>
          <length>0.04</length>
        </cylinder>
      </geometry>
    </collision>

    <visual name="tire">
      <geometry>
        <cylinder>
          <radius>0.055</radius>
          <length>0.04</length>
        </cylinder>
      </geometry>
      <material>
        <script>
          <uri>file://media/materials/scripts/gazebo.material</uri>
          <name>Gazebo/DarkGrey</name>
        </script>
      </material>
    </visual>

  </link>

  
  <joint type="revolute" name="front_right_steer_joint">
    <parent>base_link</parent>
    <child>front_right_strut</child>
    <axis>
      <xyz>0 0 1</xyz> 
      <limit>
        <lower>-1</lower>
        <upper>1</upper>
        <velocity>1.0</velocity>
        <effort>25</effort>
      </limit>
    </axis>
  </joint>
  

  <joint type="revolute" name="front_right_drive_joint">
    <parent>front_right_strut</parent>
    <child>front_right_wheel</child>
    <axis>
      <xyz>0 0 1</xyz>
      <limit>
        <lower>-1.79769e+308</lower>
        <upper>1.79769e+308</upper>
      </limit>
    </axis>
  </joint>
  
  <link name="rear_left_strut">
    <inertial>
        <mass>0.01</mass>
        <inertia>
          <ixx>0.001</ixx>
          <iyy>0.001</iyy>
          <izz>0.001</izz>
        </inertia>
      </inertial>

    <pose>-0.15 0.08 -0.08 0 0 0</pose>
  </link>

  <link name="rear_left_wheel">
    <pose>-0.15 0.08 -0.08 -1.5707 0 0</pose>
    <inertial>
        <mass>0.01</mass>
        <inertia>
          <ixx>0.001</ixx>
          <iyy>0.001</iyy>
          <izz>0.001</izz>
        </inertia>
      </inertial>

    <collision name="collision">
      <geometry>
        <cylinder>
          <radius>0.055</radius>
          <length>0.04</length>
        </cylinder>
      </geometry>
    </collision>

    <visual name="tire">
      <geometry>
        <cylinder>
          <radius>0.055</radius>
          <length>0.04</length>
        </cylinder>
      </geometry>
      <material>
        <script>
          <uri>file://media/materials/scripts/gazebo.material</uri>
          <name>Gazebo/DarkGrey</name>
        </script>
      </material>
    </visual>

  </link>

  
  <joint type="fixed" name="rear_left_steer_joint">
    <parent>base_link</parent>
    <child>rear_left_strut</child>
  </joint>
  

  <joint type="revolute" name="rear_left_drive_joint">
    <parent>rear_left_strut</parent>
    <child>rear_left_wheel</child>
    <axis>
      <xyz>0 0 1</xyz>
      <limit>
        <lower>-1.79769e+308</lower>
        <upper>1.79769e+308</upper>
      </limit>
    </axis>
  </joint>
  
  <link name="rear_right_strut">
    <inertial>
        <mass>0.01</mass>
        <inertia>
          <ixx>0.001</ixx>
          <iyy>0.001</iyy>
          <izz>0.001</izz>
        </inertia>
      </inertial>

    <pose>-0.15 -0.08 -0.08 0 0 0</pose>
  </link>

  <link name="rear_right_wheel">
    <pose>-0.15 -0.08 -0.08 -1.5707 0 0</pose>
    <inertial>
        <mass>0.01</mass>
        <inertia>
          <ixx>0.001</ixx>
          <iyy>0.001</iyy>
          <izz>0.001</izz>
        </inertia>
      </inertial>

    <collision name="collision">
      <geometry>
        <cylinder>
          <radius>0.055</radius>
          <length>0.04</length>
        </cylinder>
      </geometry>
    </collision>

    <visual name="tire">
      <geometry>
        <cylinder>
          <radius>0.055</radius>
          <length>0.04</length>
        </cylinder>
      </geometry>
      <material>
        <script>
          <uri>file://media/materials/scripts/gazebo.material</uri>
          <name>Gazebo/DarkGrey</name>
        </script>
      </material>
    </visual>

  </link>

  
  <joint type="fixed" name="rear_right_steer_joint">
    <parent>base_link</parent>
    <child>rear_right_strut</child>
  </joint>
  

  <joint type="revolute" name="rear_right_drive_joint">
    <parent>rear_right_strut</parent>
    <child>rear_right_wheel</child>
    <axis>
      <xyz>0 0 1</xyz>
      <limit>
        <lower>-1.79769e+308</lower>
        <upper>1.79769e+308</upper>
      </limit>
    </axis>
  </joint>
  

  <!--
  <plugin name='p3d' filename='libgazebo_ros_p3d.so'>
    <robotNamespace>axial_scx10</robotNamespace>
    <updateRate>10</updateRate>
    <bodyName>base_link</bodyName>
    <topicName>/qualisys/axial_scx10/odom</topicName>
    <frameName>map</frameName>
    <xyzOffset>0 0 0</xyzOffset>
    <rpyOffset>0 0 0</rpyOffset>
  </plugin>
  -->

  <plugin filename="libignition-gazebo-ackermann-steering-system.so"
    name="ignition::gazebo::systems::AckermannSteering">
    <left_joint>front_left_drive_joint</left_joint>
    <left_joint>rear_left_drive_joint</left_joint>
    <right_joint>front_right_drive_joint</right_joint> 
    <right_joint>rear_right_drive_joint</right_joint> 
    <left_steering_joint>front_left_steer_joint</left_steering_joint>
    <right_steering_joint>front_right_steer_joint</right_steering_joint>
    <wheel_separation>0.16</wheel_separation>
    <kingpin_width></kingpin_width>
    <wheel_base>0.3</wheel_base>
    <steering_limit>1.0</steering_limit>
    <wheel_radius>0.055</wheel_radius>
    <odom_publish_frequency>50</odom_publish_frequency>
    <min_velocity>0</min_velocity>
    <max_velocity>1</max_velocity>
    <min_acceleration>-1</min_acceleration>
    <max_acceleration>1</max_acceleration>
    <min_jerk_minimum>-1</min_jerk_minimum>
    <min_jerk_maximum>1</min_jerk_maximum>
    <topic>/cmd_vel</topic>
    <odom_topic>/odom</odom_topic>
  </plugin>

</model>

</sdf>
<!-- vim: set et fenc=utf-8 ff=unix sts=0 sw=2 ts=2 : -->